[2024-10-02T03:25:37.401+0000] {local_task_job_runner.py:123} INFO - ::group::Pre task execution logs
[2024-10-02T03:25:37.409+0000] {taskinstance.py:2612} INFO - Dependencies all met for dep_context=non-requeueable deps ti=<TaskInstance: test_world.sleep scheduled__2021-03-11T15:00:00+00:00 [queued]>
[2024-10-02T03:25:37.413+0000] {taskinstance.py:2612} INFO - Dependencies all met for dep_context=requeueable deps ti=<TaskInstance: test_world.sleep scheduled__2021-03-11T15:00:00+00:00 [queued]>
[2024-10-02T03:25:37.413+0000] {taskinstance.py:2865} INFO - Starting attempt 1 of 4
[2024-10-02T03:25:37.420+0000] {taskinstance.py:2888} INFO - Executing <Task(BashOperator): sleep> on 2021-03-11 15:00:00+00:00
[2024-10-02T03:25:37.424+0000] {warnings.py:112} WARNING - /home/***/.local/lib/python3.12/site-packages/***/task/task_runner/standard_task_runner.py:70: DeprecationWarning: This process (pid=815) is multi-threaded, use of fork() may lead to deadlocks in the child.
  pid = os.fork()

[2024-10-02T03:25:37.425+0000] {standard_task_runner.py:72} INFO - Started process 861 to run task
[2024-10-02T03:25:37.425+0000] {standard_task_runner.py:104} INFO - Running: ['***', 'tasks', 'run', 'test_world', 'sleep', 'scheduled__2021-03-11T15:00:00+00:00', '--job-id', '158', '--raw', '--subdir', 'DAGS_FOLDER/test_world.py', '--cfg-path', '/tmp/tmpjrlv1ytv']
[2024-10-02T03:25:37.426+0000] {standard_task_runner.py:105} INFO - Job 158: Subtask sleep
[2024-10-02T03:25:37.452+0000] {task_command.py:467} INFO - Running <TaskInstance: test_world.sleep scheduled__2021-03-11T15:00:00+00:00 [running]> on host 8dd91c37f153
[2024-10-02T03:25:37.497+0000] {taskinstance.py:3131} INFO - Exporting env vars: AIRFLOW_CTX_DAG_OWNER='***' AIRFLOW_CTX_DAG_ID='test_world' AIRFLOW_CTX_TASK_ID='sleep' AIRFLOW_CTX_EXECUTION_DATE='2021-03-11T15:00:00+00:00' AIRFLOW_CTX_TRY_NUMBER='1' AIRFLOW_CTX_DAG_RUN_ID='scheduled__2021-03-11T15:00:00+00:00'
[2024-10-02T03:25:37.498+0000] {logging_mixin.py:190} INFO - Task instance is in running state
[2024-10-02T03:25:37.499+0000] {logging_mixin.py:190} INFO -  Previous state of the Task instance: queued
[2024-10-02T03:25:37.499+0000] {logging_mixin.py:190} INFO - Current task name:sleep state:running start_date:2024-10-02 03:25:37.409626+00:00
[2024-10-02T03:25:37.499+0000] {logging_mixin.py:190} INFO - Dag name:test_world and current dag run status:running
[2024-10-02T03:25:37.499+0000] {taskinstance.py:731} INFO - ::endgroup::
[2024-10-02T03:25:37.499+0000] {subprocess.py:63} INFO - Tmp dir root location: /tmp
[2024-10-02T03:25:37.500+0000] {subprocess.py:75} INFO - Running command: ['/usr/bin/bash', '-c', 'sleep 5']
[2024-10-02T03:25:37.521+0000] {subprocess.py:86} INFO - Output:
[2024-10-02T03:25:42.531+0000] {subprocess.py:97} INFO - Command exited with return code 0
[2024-10-02T03:25:42.572+0000] {taskinstance.py:340} INFO - ::group::Post task execution logs
[2024-10-02T03:25:42.573+0000] {taskinstance.py:352} INFO - Marking task as SUCCESS. dag_id=test_world, task_id=sleep, run_id=scheduled__2021-03-11T15:00:00+00:00, execution_date=20210311T150000, start_date=20241002T032537, end_date=20241002T032542
[2024-10-02T03:25:43.589+0000] {standard_task_runner.py:124} ERROR - Failed to execute job 158 for task sleep ((psycopg2.errors.DeadlockDetected) deadlock detected
DETAIL:  Process 5156 waits for ShareLock on transaction 18196; blocked by process 64.
Process 64 waits for ShareLock on transaction 18213; blocked by process 5156.
HINT:  See server log for query details.
CONTEXT:  while updating tuple (1,68) in relation "dag_run"

[SQL: UPDATE dag_run SET last_scheduling_decision=%(last_scheduling_decision)s, updated_at=%(updated_at)s WHERE dag_run.id = %(dag_run_id)s]
[parameters: {'last_scheduling_decision': datetime.datetime(2024, 10, 2, 3, 25, 36, 731543, tzinfo=Timezone('UTC')), 'updated_at': datetime.datetime(2024, 10, 2, 3, 25, 36, 743242, tzinfo=Timezone('UTC')), 'dag_run_id': 73}]
(Background on this error at: https://sqlalche.me/e/14/e3q8); 861)
Traceback (most recent call last):
  File "/home/airflow/.local/lib/python3.12/site-packages/sqlalchemy/engine/base.py", line 1910, in _execute_context
    self.dialect.do_execute(
  File "/home/airflow/.local/lib/python3.12/site-packages/sqlalchemy/engine/default.py", line 736, in do_execute
    cursor.execute(statement, parameters)
psycopg2.errors.DeadlockDetected: deadlock detected
DETAIL:  Process 5156 waits for ShareLock on transaction 18196; blocked by process 64.
Process 64 waits for ShareLock on transaction 18213; blocked by process 5156.
HINT:  See server log for query details.
CONTEXT:  while updating tuple (1,68) in relation "dag_run"


The above exception was the direct cause of the following exception:

Traceback (most recent call last):
  File "/home/airflow/.local/lib/python3.12/site-packages/airflow/task/task_runner/standard_task_runner.py", line 117, in _start_by_fork
    ret = args.func(args, dag=self.dag)
          ^^^^^^^^^^^^^^^^^^^^^^^^^^^^^
  File "/home/airflow/.local/lib/python3.12/site-packages/airflow/cli/cli_config.py", line 49, in command
    return func(*args, **kwargs)
           ^^^^^^^^^^^^^^^^^^^^^
  File "/home/airflow/.local/lib/python3.12/site-packages/airflow/utils/cli.py", line 115, in wrapper
    return f(*args, **kwargs)
           ^^^^^^^^^^^^^^^^^^
  File "/home/airflow/.local/lib/python3.12/site-packages/airflow/cli/commands/task_command.py", line 483, in task_run
    task_return_code = _run_task_by_selected_method(args, _dag, ti)
                       ^^^^^^^^^^^^^^^^^^^^^^^^^^^^^^^^^^^^^^^^^^^^
  File "/home/airflow/.local/lib/python3.12/site-packages/airflow/cli/commands/task_command.py", line 256, in _run_task_by_selected_method
    return _run_raw_task(args, ti)
           ^^^^^^^^^^^^^^^^^^^^^^^
  File "/home/airflow/.local/lib/python3.12/site-packages/airflow/cli/commands/task_command.py", line 341, in _run_raw_task
    return ti._run_raw_task(
           ^^^^^^^^^^^^^^^^^
  File "/home/airflow/.local/lib/python3.12/site-packages/airflow/utils/session.py", line 97, in wrapper
    return func(*args, session=session, **kwargs)
           ^^^^^^^^^^^^^^^^^^^^^^^^^^^^^^^^^^^^^^
  File "/home/airflow/.local/lib/python3.12/site-packages/airflow/models/taskinstance.py", line 3004, in _run_raw_task
    return _run_raw_task(
           ^^^^^^^^^^^^^^
  File "/home/airflow/.local/lib/python3.12/site-packages/airflow/models/taskinstance.py", line 365, in _run_raw_task
    TaskInstance.save_to_db(ti=ti, session=session)
  File "/home/airflow/.local/lib/python3.12/site-packages/airflow/api_internal/internal_api_call.py", line 139, in wrapper
    return func(*args, **kwargs)
           ^^^^^^^^^^^^^^^^^^^^^
  File "/home/airflow/.local/lib/python3.12/site-packages/airflow/utils/session.py", line 94, in wrapper
    return func(*args, **kwargs)
           ^^^^^^^^^^^^^^^^^^^^^
  File "/home/airflow/.local/lib/python3.12/site-packages/airflow/models/taskinstance.py", line 3399, in save_to_db
    session.flush()
  File "/home/airflow/.local/lib/python3.12/site-packages/sqlalchemy/orm/session.py", line 3449, in flush
    self._flush(objects)
  File "/home/airflow/.local/lib/python3.12/site-packages/sqlalchemy/orm/session.py", line 3588, in _flush
    with util.safe_reraise():
         ^^^^^^^^^^^^^^^^^^^
  File "/home/airflow/.local/lib/python3.12/site-packages/sqlalchemy/util/langhelpers.py", line 70, in __exit__
    compat.raise_(
  File "/home/airflow/.local/lib/python3.12/site-packages/sqlalchemy/util/compat.py", line 211, in raise_
    raise exception
  File "/home/airflow/.local/lib/python3.12/site-packages/sqlalchemy/orm/session.py", line 3549, in _flush
    flush_context.execute()
  File "/home/airflow/.local/lib/python3.12/site-packages/sqlalchemy/orm/unitofwork.py", line 456, in execute
    rec.execute(self)
  File "/home/airflow/.local/lib/python3.12/site-packages/sqlalchemy/orm/unitofwork.py", line 630, in execute
    util.preloaded.orm_persistence.save_obj(
  File "/home/airflow/.local/lib/python3.12/site-packages/sqlalchemy/orm/persistence.py", line 237, in save_obj
    _emit_update_statements(
  File "/home/airflow/.local/lib/python3.12/site-packages/sqlalchemy/orm/persistence.py", line 1001, in _emit_update_statements
    c = connection._execute_20(
        ^^^^^^^^^^^^^^^^^^^^^^^
  File "/home/airflow/.local/lib/python3.12/site-packages/sqlalchemy/engine/base.py", line 1710, in _execute_20
    return meth(self, args_10style, kwargs_10style, execution_options)
           ^^^^^^^^^^^^^^^^^^^^^^^^^^^^^^^^^^^^^^^^^^^^^^^^^^^^^^^^^^^
  File "/home/airflow/.local/lib/python3.12/site-packages/sqlalchemy/sql/elements.py", line 334, in _execute_on_connection
    return connection._execute_clauseelement(
           ^^^^^^^^^^^^^^^^^^^^^^^^^^^^^^^^^^
  File "/home/airflow/.local/lib/python3.12/site-packages/sqlalchemy/engine/base.py", line 1577, in _execute_clauseelement
    ret = self._execute_context(
          ^^^^^^^^^^^^^^^^^^^^^^
  File "/home/airflow/.local/lib/python3.12/site-packages/sqlalchemy/engine/base.py", line 1953, in _execute_context
    self._handle_dbapi_exception(
  File "/home/airflow/.local/lib/python3.12/site-packages/sqlalchemy/engine/base.py", line 2134, in _handle_dbapi_exception
    util.raise_(
  File "/home/airflow/.local/lib/python3.12/site-packages/sqlalchemy/util/compat.py", line 211, in raise_
    raise exception
  File "/home/airflow/.local/lib/python3.12/site-packages/sqlalchemy/engine/base.py", line 1910, in _execute_context
    self.dialect.do_execute(
  File "/home/airflow/.local/lib/python3.12/site-packages/sqlalchemy/engine/default.py", line 736, in do_execute
    cursor.execute(statement, parameters)
sqlalchemy.exc.OperationalError: (psycopg2.errors.DeadlockDetected) deadlock detected
DETAIL:  Process 5156 waits for ShareLock on transaction 18196; blocked by process 64.
Process 64 waits for ShareLock on transaction 18213; blocked by process 5156.
HINT:  See server log for query details.
CONTEXT:  while updating tuple (1,68) in relation "dag_run"

[SQL: UPDATE dag_run SET last_scheduling_decision=%(last_scheduling_decision)s, updated_at=%(updated_at)s WHERE dag_run.id = %(dag_run_id)s]
[parameters: {'last_scheduling_decision': datetime.datetime(2024, 10, 2, 3, 25, 36, 731543, tzinfo=Timezone('UTC')), 'updated_at': datetime.datetime(2024, 10, 2, 3, 25, 36, 743242, tzinfo=Timezone('UTC')), 'dag_run_id': 73}]
(Background on this error at: https://sqlalche.me/e/14/e3q8)
[2024-10-02T03:25:43.652+0000] {local_task_job_runner.py:266} INFO - Task exited with return code 1
[2024-10-02T03:25:43.667+0000] {local_task_job_runner.py:245} INFO - ::endgroup::
